<?xml version="1.0"?>
<robot xmlns:xacro="http://www.ros.org/wiki/xacro" name="robot">
    <xacro:macro name="arm" params="prefix">

        <!-- links -->
        <link name="${prefix}_base_fixed">
            <visual>
            <origin rpy="0 0 0" xyz="0 0 0.4"/>
            <geometry>
                <box size="0.3 0.5 1"/>
            </geometry>
            </visual>

            <collision>
            <origin rpy="0 0 0" xyz="0 0 0.4"/>
            <geometry>
                <box size="0.3 0.3 0.8"/>
            </geometry>
            </collision>

            <inertial>
            <mass value="0.5"/>
            <inertia ixx="0.4" ixy="0.0" ixz="0.0" iyy="0.4" iyz="0.0" izz="0.2"/>
            </inertial>
        </link>

        <link name="${prefix}_base">
            <visual>
            <origin rpy="0.0 0 0" xyz="0 0 0"/>
            <geometry>
                <mesh filename="package://arm_urdf/meshes/Base.dae"/>
            </geometry>
            </visual>

            <collision>
            <origin rpy="0.0 0 0" xyz="0 0 0"/>
            <geometry>
                <mesh filename="package://arm_urdf/meshes/Base.dae"/>
            </geometry>
            </collision>

            <inertial>
            <mass value="0.5"/>
            <inertia ixx="0.4" ixy="0.0" ixz="0.0" iyy="0.4" iyz="0.0" izz="0.2"/>
            </inertial>
        </link>

        <link name="${prefix}_bridge">
            <visual>
            <origin rpy="0.0 0 ${radians(-90)}" xyz="0.07 0 0.104"/>
            <geometry>
                <mesh filename="package://arm_urdf/meshes/Bridge.dae"/>
            </geometry>
            </visual>

            <collision>
            <origin rpy="0.0 0 ${radians(-90)}" xyz="0.07 0 0.104"/>
            <geometry>
                <mesh filename="package://arm_urdf/meshes/Bridge.dae"/>
            </geometry>
            </collision>

            <inertial>
            <mass value="0.5"/>
            <inertia ixx="0.4" ixy="0.0" ixz="0.0" iyy="0.4" iyz="0.0" izz="0.2"/>
            </inertial>
        </link>

        <link name="${prefix}_bridge2">
            <visual>
            <origin rpy="0.0 0 ${radians(90)}" xyz="-0.07 0 0.104"/>
            <geometry>
                <mesh filename="package://arm_urdf/meshes/Bridge.dae"/>
            </geometry>
            </visual>

            <collision>
            <origin rpy="0.0 0 ${radians(90)}" xyz="-0.07 0 0.104"/>
            <geometry>
                <mesh filename="package://arm_urdf/meshes/Bridge.dae"/>
            </geometry>
            </collision>

            <inertial>
            <mass value="0.5"/>
            <inertia ixx="0.4" ixy="0.0" ixz="0.0" iyy="0.4" iyz="0.0" izz="0.2"/>
            </inertial>
        </link>

        <link name="${prefix}_housing">
            <visual>
            <origin rpy="0.0 0 0" xyz="0 0 0"/>
            <geometry>
                <mesh filename="package://arm_urdf/meshes/Housing.dae"/>
            </geometry>
            </visual>

            <collision>
            <origin rpy="0.0 0 0" xyz="0 0 0"/>
            <geometry>
                <mesh filename="package://arm_urdf/meshes/Housing.dae"/>
            </geometry>
            </collision>

            <inertial>
            <mass value="0.5"/>
            <inertia ixx="0.4" ixy="0.0" ixz="0.0" iyy="0.4" iyz="0.0" izz="0.2"/>
            </inertial>
        </link>

        <link name="${prefix}_wrist_link">
            <visual>
            <origin rpy="0.0 0 0" xyz="0 0 0"/>
            <geometry>
                <mesh filename="package://arm_urdf/meshes/Wrist Link.dae"/>
            </geometry>
            </visual>

            <collision>
            <origin rpy="0.0 0 0" xyz="0 0 0"/>
            <geometry>
                <mesh filename="package://arm_urdf/meshes/Wrist Link.dae"/>
            </geometry>
            </collision>

            <inertial>
            <mass value="0.5"/>
            <inertia ixx="0.4" ixy="0.0" ixz="0.0" iyy="0.4" iyz="0.0" izz="0.2"/>
            </inertial>
        </link>

        <link name="${prefix}_wrist_cuff">
            <visual>
            <origin rpy="0.0 ${radians(180)} 0" xyz="0 0.027 -0.0255"/>
            <geometry>
                <mesh filename="package://arm_urdf/meshes/Wrist Cuff.dae"/>
            </geometry>
            </visual>

            <collision>
            <origin rpy="0.0 ${radians(180)} 0" xyz="0 0.027 -0.0255"/>
            <geometry>
                <mesh filename="package://arm_urdf/meshes/Wrist Cuff.dae"/>
            </geometry>
            </collision>

            <inertial>
            <mass value="0.5"/>
            <inertia ixx="0.4" ixy="0.0" ixz="0.0" iyy="0.4" iyz="0.0" izz="0.2"/>
            </inertial>
        </link>

        <!-- camera link -->
        <link name="${prefix}_camera">
            <visual>
            <origin rpy="0.0 ${radians(180)} 0" xyz="0 0.06 0.043"/>
            <geometry>
                <box size="0.05 0.05 0.08"/>
            </geometry>
            </visual>

            <collision>
            <origin rpy="0.0 ${radians(180)} 0" xyz="0 0.06 0.043"/>
            <geometry>
                <box size="0.05 0.05 0.08"/>
            </geometry>
            </collision>

            <inertial>
            <mass value="0.5"/>
            <inertia ixx="0.4" ixy="0.0" ixz="0.0" iyy="0.4" iyz="0.0" izz="0.2"/>
            </inertial>
        </link>


        <!-- joints -->
        <!-- joint names defined like so: ${prefix}_<parent>_<child>_joint -->
        <joint name="${prefix}_base_fixed_base_joint" type="revolute">
            <origin rpy="0 ${radians(90)} 0" xyz="0.15 0 0.6"/>
            <axis xyz="0 0 1"/>
            <limit effort="1000.0" lower="${radians(-180)}" upper="${radians(180)}" velocity="0.5"/>
            <parent link="${prefix}_base_fixed" />
            <child link="${prefix}_base" />

            <dynamics D="1" K="7000" mu_coulomb="0" mu_viscous="16" damping="0.003" friction="0.0"/>
        </joint>

        <joint name="${prefix}_base_bridge_joint" type="revolute">
            <origin rpy="0.0 0 0" xyz="0.0 0 0.165"/>
            <axis xyz="1 0 0"/>
            <limit effort="1000.0" lower="${radians(-120)}" upper="${radians(120)}" velocity="0.5"/>
            <parent link="${prefix}_base" />
            <child link="${prefix}_bridge" />

            <dynamics D="1" K="7000" mu_coulomb="0" mu_viscous="16" damping="0.003" friction="0.0"/>
        </joint>
        
        <joint name="${prefix}_bridge_bridge2_joint" type="fixed">
            <origin rpy="0.0 0 0" xyz="0.0 0 0"/>
            <parent link="${prefix}_bridge" />
            <child link="${prefix}_bridge2" />
        </joint>

        <joint name="${prefix}_bridge_housing_joint" type="revolute">
            <origin rpy="0 0 0" xyz="0 0 0.24875"/>
            <axis xyz="1 0 0"/>
            <limit effort="1000.0" lower="${radians(-165)}" upper="${radians(165)}" velocity="0.5"/>
            <parent link="${prefix}_bridge" />
            <child link="${prefix}_housing" />

            <dynamics D="1" K="7000" mu_coulomb="0" mu_viscous="16" damping="0.003" friction="0.0"/>
        </joint>

        <joint name="${prefix}_housing_wrist_link_joint" type="revolute">
            <origin rpy="0 0 0" xyz="0 0 0.045"/>
            <axis xyz="0 0 1"/>
            <limit effort="1000.0" lower="${radians(-180)}" upper="${radians(180)}" velocity="0.5"/>
            <parent link="${prefix}_housing" />
            <child link="${prefix}_wrist_link" />

            <dynamics D="1" K="7000" mu_coulomb="0" mu_viscous="16" damping="0.003" friction="0.0"/>
        </joint>

        <joint name="${prefix}_wrist_link_wrist_cuff_joint" type="revolute">
            <origin rpy="0 0 0" xyz="0 0.0 0.122"/>
            <axis xyz="1 0 0"/>
            <limit effort="1000.0" lower="${radians(-85)}" upper="${radians(85)}" velocity="0.5"/>
            <parent link="${prefix}_wrist_link" />
            <child link="${prefix}_wrist_cuff" />

            <dynamics D="1" K="7000" mu_coulomb="0" mu_viscous="16" damping="0.003" friction="0.0"/>
        </joint>

        <!-- camera joint -->
        <joint name="${prefix}_wrist_link_camera_joint" type="fixed">
            <origin rpy="0 0 0" xyz="0 0.0 0"/>
            <parent link="${prefix}_wrist_link" />
            <child link="${prefix}_camera" />
        </joint>

    </xacro:macro>
</robot>